Traceback (most recent call last):
  File "/usr/local/lib/python3.10/site-packages/jupyter_cache/executors/utils.py", line 51, in single_nb_execution
    executenb(
  File "/usr/local/lib/python3.10/site-packages/nbclient/client.py", line 1269, in execute
    return NotebookClient(nb=nb, resources=resources, km=km, **kwargs).execute()
  File "/usr/local/lib/python3.10/site-packages/nbclient/util.py", line 85, in wrapped
    return just_run(coro(*args, **kwargs))
  File "/usr/local/lib/python3.10/site-packages/nbclient/util.py", line 60, in just_run
    return loop.run_until_complete(coro)
  File "/usr/local/Cellar/python@3.10/3.10.6_1/Frameworks/Python.framework/Versions/3.10/lib/python3.10/asyncio/base_events.py", line 646, in run_until_complete
    return future.result()
  File "/usr/local/lib/python3.10/site-packages/nbclient/client.py", line 707, in async_execute
    await self.async_execute_cell(
  File "/usr/local/lib/python3.10/site-packages/nbclient/client.py", line 1025, in async_execute_cell
    await self._check_raise_for_error(cell, cell_index, exec_reply)
  File "/usr/local/lib/python3.10/site-packages/nbclient/client.py", line 919, in _check_raise_for_error
    raise CellExecutionError.from_cell_and_msg(cell, exec_reply_content)
nbclient.exceptions.CellExecutionError: An error occurred while executing the following cell:
------------------
psi = psi_ho(0)*c(t)[0] + psi_ho[1]*c(t)[1]
------------------

[0;31m---------------------------------------------------------------------------[0m
[0;31mNameError[0m                                 Traceback (most recent call last)
Cell [0;32mIn [4], line 1[0m
[0;32m----> 1[0m psi [38;5;241m=[39m [43mpsi_ho[49m([38;5;241m0[39m)[38;5;241m*[39mc(t)[[38;5;241m0[39m] [38;5;241m+[39m psi_ho[[38;5;241m1[39m][38;5;241m*[39mc(t)[[38;5;241m1[39m]

[0;31mNameError[0m: name 'psi_ho' is not defined
NameError: name 'psi_ho' is not defined

